Workbook

Sheet Checklist Meseros
A1: MESEROS. GPS GASTRONOMICO
A2: Lista de Verificación — Organigrama de Meseros
A4: Restaurante: | C4: Fecha:
A5: Evaluador: | C5: Turno / Servicio:
A7: RESULTADO DE LA EVALUACIÓN
A8: Total de respuestas SÍ | B8: =COUNTIF(B16:B60,"X") -> 0 | C8: Total de respuestas NO | D8: =COUNTIF(C16:C60,"X") -> 0
A9: Ítems evaluados (SÍ + NO) | B9: =B8+D8 -> 0 | C9: % de cumplimiento | D9: =IFERROR(B8/B9,0) -> 0
A10: CALIFICACIÓN FINAL | C10: =IF(B9=0,"Sin datos",IF(D9>=0.9,"EXCELENTE",IF(D9>=0.75,"MUY BUENO",IF(D9>=0.6,"ACEPTABLE",IF(D9>=0.4,"RIESGO DE PÉRDIDA DE RENTABILIDAD","SERVICIO CRÍTICO – INTERVENCIÓN INMEDIATA"))))) -> Sin datos
A12: Instrucciones: marque una X en la columna SÍ o NO de cada ítem. Deje en blanco los no aplicables (no se contabilizan). Los totales y la calificación se calculan automáticamente.
A14: 1. ANÁLISIS DE DEMANDA Y HORARIOS PICO
A15: PREGUNTA | B15: SÍ | C15: NO | D15: OBSERVACIONES
A16: ¿Tenés identificados los horarios de mayor flujo (picos) de cada día de la semana?
A17: ¿Registrás la cantidad de mesas y comensales por franja horaria?
A18: ¿Diferenciás la demanda entre días de semana y fines de semana?
A19: ¿Usás el histórico de ventas o reservas para anticipar la demanda?
A20: ¿Revisás y actualizás los horarios pico de forma periódica?
A22: 2. RATIO Y DOTACIÓN DE MESEROS
A23: PREGUNTA | B23: SÍ | C23: NO | D23: OBSERVACIONES
A24: ¿Definiste un ratio de comensales por mesero (por ejemplo, 20 por mesero)?
A25: ¿El ratio está ajustado al tipo de servicio (rápido, casual, fine dining)?
A26: ¿Calculás la cantidad de meseros necesarios por franja según ese ratio?
A27: ¿Contemplás un mesero de apoyo o runner en los picos?
A28: ¿Ajustás la dotación cuando cambia la demanda prevista?
A30: 3. ZONAS / ÁREAS DE ATENCIÓN
A31: PREGUNTA | B31: SÍ | C31: NO | D31: OBSERVACIONES
A32: ¿El salón está dividido en zonas o áreas de atención definidas?
A33: ¿Cada zona tiene asignada una cantidad mínima de meseros?
A34: ¿La cantidad de mesas por zona es equilibrada y razonable?
A35: ¿Está claro quién cubre cada zona en cada turno?
A36: ¿Se cubren también la barra, la terraza y los sectores especiales?
A38: 4. ASIGNACIÓN DE PERSONAL Y NOMBRES
A39: PREGUNTA | B39: SÍ | C39: NO | D39: OBSERVACIONES
A40: ¿Cada franja horaria tiene meseros asignados por nombre?
A41: ¿El calendario de colaboradores está documentado y visible?
A42: ¿Los meseros conocen su horario y su zona con anticipación?
A43: ¿La carga de trabajo está repartida de forma equitativa?
A44: ¿Se respetan los descansos y la jornada legal de cada colaborador?
A46: 5. EVENTOS ESPECIALES
A47: PREGUNTA | B47: SÍ | C47: NO | D47: OBSERVACIONES
A48: ¿Tenés un registro de eventos especiales con fecha y horario?
...

Sheet Bandas y Resumen
A1: BANDAS DE CALIFICACIÓN
A2: % de cumplimiento | B2: Calificación | D2: Acción
A3: Mayor o igual a 90% | B3: Excelente | D3: Sostener y documentar
A4: 75% – 89% | B4: Muy bueno | D4: Ajustar pendientes
A5: 60% – 74% | B5: Aceptable | D5: Plan de mejora
A6: 40% – 59% | B6: Riesgo de mala atención | D6: Intervención prioritaria
A7: Menor a 40% | B7: Crítico – intervención inmediata | D7: Acción urgente
A9: RESUMEN POR CATEGORÍA
A10: Categoría | B10: SÍ | C10: NO | D10: % Cumpl.
A11: 1. ANÁLISIS DE DEMANDA Y HORARIOS PICO | B11: =COUNTIF('Checklist Meseros'!B16:B20,"X") -> 0 | C11: =COUNTIF('Checklist Meseros'!C16:C20,"X") -> 0 | D11: =IFERROR(B11/(B11+C11),"-") -> -
A12: 2. RATIO Y DOTACIÓN DE MESEROS | B12: =COUNTIF('Checklist Meseros'!B24:B28,"X") -> 0 | C12: =COUNTIF('Checklist Meseros'!C24:C28,"X") -> 0 | D12: =IFERROR(B12/(B12+C12),"-") -> -
A13: 3. ZONAS / ÁREAS DE ATENCIÓN | B13: =COUNTIF('Checklist Meseros'!B32:B36,"X") -> 0 | C13: =COUNTIF('Checklist Meseros'!C32:C36,"X") -> 0 | D13: =IFERROR(B13/(B13+C13),"-") -> -
A14: 4. ASIGNACIÓN DE PERSONAL Y NOMBRES | B14: =COUNTIF('Checklist Meseros'!B40:B44,"X") -> 0 | C14: =COUNTIF('Checklist Meseros'!C40:C44,"X") -> 0 | D14: =IFERROR(B14/(B14+C14),"-") -> -
A15: 5. EVENTOS ESPECIALES | B15: =COUNTIF('Checklist Meseros'!B48:B52,"X") -> 0 | C15: =COUNTIF('Checklist Meseros'!C48:C52,"X") -> 0 | D15: =IFERROR(B15/(B15+C15),"-") -> -
A16: 6. CONTINGENCIAS Y COBERTURA | B16: =COUNTIF('Checklist Meseros'!B56:B60,"X") -> 0 | C16: =COUNTIF('Checklist Meseros'!C56:C60,"X") -> 0 | D16: =IFERROR(B16/(B16+C16),"-") -> -
