Workbook

Sheet Checklist Cocina
A1: MISE EN PLACE GPS GASTRONOMICO
A2: Lista de Verificación — Personal de Cocina y Producción
A4: Restaurante: | C4: Fecha:
A5: Evaluador: | C5: Turno / Servicio:
A7: RESULTADO DE LA EVALUACIÓN
A8: Total de respuestas SÍ | B8: =COUNTIF(B16:B74,"X") -> 0 | C8: Total de respuestas NO | D8: =COUNTIF(C16:C74,"X") -> 0
A9: Ítems evaluados (SÍ + NO) | B9: =B8+D8 -> 0 | C9: % de cumplimiento | D9: =IFERROR(B8/B9,0) -> 0
A10: CALIFICACIÓN FINAL | C10: =IF(B9=0,"Sin datos",IF(D9>=0.9,"EXCELENTE",IF(D9>=0.75,"MUY BUENO",IF(D9>=0.6,"ACEPTABLE",IF(D9>=0.4,"RIESGO DE PÉRDIDA DE RENTABILIDAD","SERVICIO CRÍTICO – INTERVENCIÓN INMEDIATA"))))) -> Sin datos
A12: Instrucciones: marque una X en la columna SÍ o NO de cada ítem. Deje en blanco los no aplicables (no se contabilizan). Los totales y la calificación se calculan automáticamente.
A14: 1. ESTRUCTURA Y ROLES DE COCINA
A15: PREGUNTA | B15: SÍ | C15: NO | D15: OBSERVACIONES
A16: ¿Está definido el organigrama de cocina con sus roles (bacheros, ayudantes, cocineros, expo)?
A17: ¿Cada puesto tiene funciones y responsabilidades claras y por escrito?
A18: ¿Existe un responsable de cocina (jefe o chef) por turno?
A19: ¿El rol de expo está cubierto en los turnos de mayor flujo?
A20: ¿La cantidad de personal por rol está acorde al volumen de trabajo?
A21: ¿La estructura de la cocina se revisa cuando cambia el volumen o el menú?
A23: 2. DOTACIÓN Y PLANIFICACIÓN DE TURNOS
A24: PREGUNTA | B24: SÍ | C24: NO | D24: OBSERVACIONES
A25: ¿La dotación de cada turno está definida según la carga de trabajo del día?
A26: ¿Se refuerza el personal los días pico (viernes y sábados)?
A27: ¿El calendario de turnos está armado y comunicado con anticipación?
A28: ¿Cada turno tiene horario de entrada y salida definido?
A29: ¿Se controla que la dotación asignada cubra la dotación necesaria?
A30: ¿Existe un plan de reemplazo ante ausencias o picos imprevistos?
A31: ¿Se evita el exceso de personal en los turnos de baja demanda?
A33: 3. PERSONAL DE PRODUCCIÓN (MISE EN PLACE)
A34: PREGUNTA | B34: SÍ | C34: NO | D34: OBSERVACIONES
A35: ¿Hay personal de producción asignado para el mise en place y los preelaborados?
A36: ¿Están definidos los días y horarios de producción?
A37: ¿La cantidad de empleados de producción está dimensionada según la demanda?
A38: ¿Las tareas de producción están listadas y asignadas a un responsable?
A39: ¿Se coordina la producción con la apertura del servicio (tiempos)?
A40: ¿Se controlan las horas y las horas-hombre de producción?
A41: ¿Se mide el rendimiento de la producción (lo producido vs. lo planificado)?
A43: 4. JORNADA, HORAS Y DESCANSOS
A44: PREGUNTA | B44: SÍ | C44: NO | D44: OBSERVACIONES
A45: ¿Se registran las horas trabajadas por cada empleado de cocina?
A46: ¿Se respeta la jornada legal y los descansos entre turnos?
A47: ¿Se controla la carga horaria semanal para evitar excesos?
...

Sheet Bandas y Resumen
A1: BANDAS DE CALIFICACIÓN
A2: % de cumplimiento | B2: Calificación | D2: Acción
A3: Mayor o igual a 90% | B3: Excelente | D3: Sostener y documentar
A4: 75% – 89% | B4: Muy bueno | D4: Ajustar pendientes
A5: 60% – 74% | B5: Aceptable | D5: Plan de mejora
A6: 40% – 59% | B6: Riesgo operativo | D6: Intervención prioritaria
A7: Menor a 40% | B7: Crítico – intervención inmediata | D7: Acción urgente
A9: RESUMEN POR CATEGORÍA
A10: Categoría | B10: SÍ | C10: NO | D10: % Cumpl.
A11: 1. ESTRUCTURA Y ROLES DE COCINA | B11: =COUNTIF('Checklist Cocina'!B16:B21,"X") -> 0 | C11: =COUNTIF('Checklist Cocina'!C16:C21,"X") -> 0 | D11: =IFERROR(B11/(B11+C11),"-") -> -
A12: 2. DOTACIÓN Y PLANIFICACIÓN DE TURNOS | B12: =COUNTIF('Checklist Cocina'!B25:B31,"X") -> 0 | C12: =COUNTIF('Checklist Cocina'!C25:C31,"X") -> 0 | D12: =IFERROR(B12/(B12+C12),"-") -> -
A13: 3. PERSONAL DE PRODUCCIÓN (MISE EN PLACE) | B13: =COUNTIF('Checklist Cocina'!B35:B41,"X") -> 0 | C13: =COUNTIF('Checklist Cocina'!C35:C41,"X") -> 0 | D13: =IFERROR(B13/(B13+C13),"-") -> -
A14: 4. JORNADA, HORAS Y DESCANSOS | B14: =COUNTIF('Checklist Cocina'!B45:B49,"X") -> 0 | C14: =COUNTIF('Checklist Cocina'!C45:C49,"X") -> 0 | D14: =IFERROR(B14/(B14+C14),"-") -> -
A15: 5. CAPACITACIÓN Y POLIVALENCIA | B15: =COUNTIF('Checklist Cocina'!B53:B58,"X") -> 0 | C15: =COUNTIF('Checklist Cocina'!C53:C58,"X") -> 0 | D15: =IFERROR(B15/(B15+C15),"-") -> -
A16: 6. HIGIENE, SEGURIDAD Y CLIMA LABORAL | B16: =COUNTIF('Checklist Cocina'!B62:B66,"X") -> 0 | C16: =COUNTIF('Checklist Cocina'!C62:C66,"X") -> 0 | D16: =IFERROR(B16/(B16+C16),"-") -> -
A17: 7. PRODUCTIVIDAD Y COSTO LABORAL | B17: =COUNTIF('Checklist Cocina'!B70:B74,"X") -> 0 | C17: =COUNTIF('Checklist Cocina'!C70:C74,"X") -> 0 | D17: =IFERROR(B17/(B17+C17),"-") -> -
