Workbook

Sheet Checklist Hospitalidad
A1: HOSPITALIDAD. GPS GASTRONOMICO
A2: Lista de Verificación — Módulo de Hospitalidad en el Restaurante
A4: Restaurante: | C4: Fecha:
A5: Evaluador: | C5: Turno / Servicio:
A7: RESULTADO DE LA EVALUACIÓN
A8: Total de respuestas SÍ | B8: =COUNTIF(B17:B168,"X") -> 0 | C8: Total de respuestas NO | D8: =COUNTIF(C17:C168,"X") -> 0
A9: Ítems evaluados (SÍ + NO) | B9: =B8+D8 -> 0 | C9: % de cumplimiento | D9: =IFERROR(B8/B9,0) -> 0
A10: CALIFICACIÓN FINAL | C10: =IF(B9=0,"Sin datos",IF(D9>=0.9,"EXCELENTE",IF(D9>=0.75,"MUY BUENO",IF(D9>=0.6,"ACEPTABLE",IF(D9>=0.4,"RIESGO DE PÉRDIDA DE CLIENTES","SERVICIO CRÍTICO – INTERVENCIÓN INMEDIATA"))))) -> Sin datos
A12: Instrucciones: marque una X en la columna SÍ o NO de cada ítem. Deje en blanco los no aplicables (no se contabilizan). Los totales y la calificación se calculan automáticamente.
A14: 1. RECEPCIÓN / HOSTESS
A15: Si el restaurante SÍ tiene hostess
A16: PREGUNTA | B16: SÍ | C16: NO | D16: OBSERVACIONES
A17: hostess recibe al cliente em menos de 30 segundos
A18: ¿Saluda con contacto visual y una sonrisa genuina?
A19: ¿Pregunta si el cliente tiene reserva y a nombre de quién?
A20: ¿Confirma el número de comensales antes de asignar la mesa?
A21: ¿Acompaña al cliente hasta la mesa (no se limita a señalarla)?
A22: ¿Ofrece guardar abrigos o pertenencias cuando corresponde?
A23: ¿Informa un tiempo estimado cuando no hay mesa disponible?
A24: ¿Gestiona la lista de espera de forma ordenada y visible?
A25: ¿Mantiene postura y vestimenta acordes al estándar de la marca?
A26: La bienvenida genero em el cliente la sensacion de SER ESPERADO?
A27: Si el restaurante NO tiene hostess
A28: PREGUNTA | B28: SÍ | C28: NO | D28: OBSERVACIONES
A29: ¿Existe un protocolo claro de quién recibe al cliente al ingresar?
A30: ¿Existe un protocolo de ubicación de los mozos que evite que se concentren en el fondo del salón o agrupados conversando?
A31: ¿Hay siempre, al menos, un mozo con la función de observar la puerta de entrada?
A32: ¿El equipo sabe qué hacer al ver ingresar a un cliente aun estando ocupado: saludarlo y avisarle que será atendido enseguida, sin dejarlo esperando sin contacto?
A33: ¿Algún miembro del equipo saluda al cliente en los primeros 30 segundos?
A34: ¿Hay señalización clara que indique si debe esperar o sentarse?
A35: ¿Se asigna la mesa según la rotación y la carga de cada sección?
A36: ¿El cliente recibe contacto visual aunque el personal esté ocupado?
A37: ¿Existe un punto de bienvenida definido (barra, caja, atril)?
A38: ¿La experiencia de bienvenida generó en el cliente la sensación de ser esperado?
A40: 2. EN LA MESA
A41: PREGUNTA | B41: SÍ | C41: NO | D41: OBSERVACIONES
A42: ¿Se consulta al cliente si es su primera visita o si ya conoce la casa?
A43: ¿La respuesta se registra en el sistema (POS/CRM) para diferenciar al cliente nuevo del recurrente?
A44: ¿Ese dato se utiliza para medir la captación de clientes nuevos y la recompra?
A45: ¿La mesa está limpia, nivelada y completamente montada al sentarse el cliente?
...

Sheet Bandas y Resumen
A1: BANDAS DE CALIFICACIÓN
A2: % de cumplimiento | B2: Calificación | D2: Acción
A3: Mayor o igual a 90% | B3: Excelente | D3: Sostener y documentar
A4: 75% – 89% | B4: Muy bueno | D4: Ajustar pendientes
A5: 60% – 74% | B5: Aceptable | D5: Plan de mejora
A6: 40% – 59% | B6: Riesgo de pérdida de clientes | D6: Intervención prioritaria
A7: Menor a 40% | B7: Servicio crítico – intervención inmediata | D7: Acción urgente
A9: RESUMEN POR CATEGORÍA
A10: Categoría | B10: SÍ | C10: NO | D10: % Cumpl.
A11: 1. RECEPCIÓN / HOSTESS | B11: =COUNTIF('Checklist Hospitalidad'!B17:B38,"X") -> 0 | C11: =COUNTIF('Checklist Hospitalidad'!C17:C38,"X") -> 0 | D11: =IFERROR(B11/(B11+C11),"-") -> -
A12: 2. EN LA MESA | B12: =COUNTIF('Checklist Hospitalidad'!B42:B51,"X") -> 0 | C12: =COUNTIF('Checklist Hospitalidad'!C42:C51,"X") -> 0 | D12: =IFERROR(B12/(B12+C12),"-") -> -
A13: 3. EL MENÚ / LA CARTA | B13: =COUNTIF('Checklist Hospitalidad'!B55:B61,"X") -> 0 | C13: =COUNTIF('Checklist Hospitalidad'!C55:C61,"X") -> 0 | D13: =IFERROR(B13/(B13+C13),"-") -> -
A14: 4. LA OFERTA / VENTA SUGESTIVA | B14: =COUNTIF('Checklist Hospitalidad'!B65:B77,"X") -> 0 | C14: =COUNTIF('Checklist Hospitalidad'!C65:C77,"X") -> 0 | D14: =IFERROR(B14/(B14+C14),"-") -> -
A15: 5. LEVANTANDO EL PEDIDO (toma de comanda) | B15: =COUNTIF('Checklist Hospitalidad'!B81:B87,"X") -> 0 | C15: =COUNTIF('Checklist Hospitalidad'!C81:C87,"X") -> 0 | D15: =IFERROR(B15/(B15+C15),"-") -> -
A16: 6. SERVICIO DE BEBIDAS Y ALIMENTOS | B16: =COUNTIF('Checklist Hospitalidad'!B91:B100,"X") -> 0 | C16: =COUNTIF('Checklist Hospitalidad'!C91:C100,"X") -> 0 | D16: =IFERROR(B16/(B16+C16),"-") -> -
A17: 7. SEGUIMIENTO DURANTE LA COMIDA | B17: =COUNTIF('Checklist Hospitalidad'!B104:B109,"X") -> 0 | C17: =COUNTIF('Checklist Hospitalidad'!C104:C109,"X") -> 0 | D17: =IFERROR(B17/(B17+C17),"-") -> -
A18: 8. MANEJO DE QUEJAS Y RECUPERACIÓN DE SERVICIO | B18: =COUNTIF('Checklist Hospitalidad'!B113:B122,"X") -> 0 | C18: =COUNTIF('Checklist Hospitalidad'!C113:C122,"X") -> 0 | D18: =IFERROR(B18/(B18+C18),"-") -> -
A19: 9. EL CIERRE Y LA CUENTA | B19: =COUNTIF('Checklist Hospitalidad'!B126:B131,"X") -> 0 | C19: =COUNTIF('Checklist Hospitalidad'!C126:C131,"X") -> 0 | D19: =IFERROR(B19/(B19+C19),"-") -> -
A20: 10. LA DESPEDIDA | B20: =COUNTIF('Checklist Hospitalidad'!B135:B139,"X") -> 0 | C20: =COUNTIF('Checklist Hospitalidad'!C135:C139,"X") -> 0 | D20: =IFERROR(B20/(B20+C20),"-") -> -
A21: 11. HOSPITALIDAD Y CONEXIÓN EMOCIONAL | B21: =COUNTIF('Checklist Hospitalidad'!B143:B152,"X") -> 0 | C21: =COUNTIF('Checklist Hospitalidad'!C143:C152,"X") -> 0 | D21: =IFERROR(B21/(B21+C21),"-") -> -
A22: 12. PRESENTACIÓN E HIGIENE DEL PERSONAL | B22: =COUNTIF('Checklist Hospitalidad'!B156:B160,"X") -> 0 | C22: =COUNTIF('Checklist Hospitalidad'!C156:C160,"X") -> 0 | D22: =IFERROR(B22/(B22+C22),"-") -> -
A23: 13. AMBIENTE Y ATMÓSFERA | B23: =COUNTIF('Checklist Hospitalidad'!B164:B168,"X") -> 0 | C23: =COUNTIF('Checklist Hospitalidad'!C164:C168,"X") -> 0 | D23: =IFERROR(B23/(B23+C23),"-") -> -
