Workbook

Sheet Organigrama Cocina
A1: ORGANIGRAMA COCINA. GPS GASTRONOMICO
A2: Restaurante: | G2: Semana del:
A5: DEFINICIÓN DE TURNOS (horario de entrada y salida)
A6: TURNO | B6: NOMBRE | C6: ENTRADA | E6: SALIDA | G6: HORAS
A7: T1 | B7: Producción / Mañana | C7: 0.33333333 | E7: 0.66666667 | G7: =IF(E7>C7,(E7-C7)*24,(E7+1-C7)*24) -> 8
A8: T2 | B8: Mediodía | C8: 0.45833333 | E8: 0.66666667 | G8: =IF(E8>C8,(E8-C8)*24,(E8+1-C8)*24) -> 5
A9: T3 | B9: Noche | C9: 0.66666667 | E9: 0.91666667 | G9: =IF(E9>C9,(E9-C9)*24,(E9+1-C9)*24) -> 6
A11: EMPLEADO | B11: NOTA | C11: LUNES | F11: MARTES | I11: MIÉRCOLES | L11: JUEVES | O11: VIERNES | R11: SÁBADO | U11: DOMINGO | X11: TOTAL HORAS
C12: T1 | D12: T2 | E12: T3 | F12: T1 | G12: T2 | H12: T3 | I12: T1 | J12: T2 | K12: T3 | L12: T1 | M12: T2 | N12: T3 | O12: T1 | P12: T2 | Q12: T3 | R12: T1 | S12: T2 | T12: T3 | U12: T1 | V12: T2 | W12: T3
A13: BACHEROS / DISHWASHER
X14: =SUM(C14:W14) -> 0
X15: =SUM(C15:W15) -> 0
X16: =SUM(C16:W16) -> 0
X17: =SUM(C17:W17) -> 0
A18: Asignados | D18: =COUNTA(D14:D17) -> 0 | E18: =COUNTA(E14:E17) -> 0 | F18: =COUNTA(F14:F17) -> 0 | G18: =COUNTA(G14:G17) -> 0 | H18: =COUNTA(H14:H17) -> 0 | I18: =COUNTA(I14:I17) -> 0 | J18: =COUNTA(J14:J17) -> 0 | K18: =COUNTA(K14:K17) -> 0 | ... W18: =COUNTA(W14:W17) -> 0 | X18: =SUM(X14:X17) -> 0
A19: Necesarios | C19: =Dotación!B8 -> 0 | D19: =Dotación!C8 -> 0 | E19: =Dotación!D8 -> 0 | F19: =Dotación!B9 -> 0 | G19: =Dotación!C9 -> 0 | H19: =Dotación!D9 -> 0 | I19: =Dotación!B10 -> 0 | J19: =Dotación!C10 -> 0 | K19: =Dotación!D10 -> 0 | L19: =Dotación!B11 -> 0 | M19: =Dotación!C11 -> 0 | N19: =Dotación!D11 -> 0 | O19: =Dotación!B12 -> 0 | P19: =Dotación!C12 -> 0 | Q19: =Dotación!D12 -> 0 | R19: =Dotación!B13 -> 0 | S19: =Dotación!C13 -> 0 | T19: =Dotación!D13 -> 0 | U19: =Dotación!B14 -> 0 | V19: =Dotación!C14 -> 0 | W19: =Dotación!D14 -> 0
A21: AYUDANTES
X22: =SUM(C22:W22) -> 0
X23: =SUM(C23:W23) -> 0
X24: =SUM(C24:W24) -> 0
X25: =SUM(C25:W25) -> 0
X26: =SUM(C26:W26) -> 0
X27: =SUM(C27:W27) -> 0
A28: Asignados | C28: 4 | D28: =COUNTA(D22:D27) -> 0 | E28: =COUNTA(E22:E27) -> 0 | F28: =COUNTA(F22:F27) -> 0 | G28: =COUNTA(G22:G27) -> 0 | H28: =COUNTA(H22:H27) -> 0 | I28: =COUNTA(I22:I27) -> 0 | J28: =COUNTA(J22:J27) -> 0 | K28: =COUNTA(K22:K27) -> 0 | ... W28: =COUNTA(W22:W27) -> 0 | X28: =SUM(X22:X27) -> 0
A29: Necesarios | C29: =Dotación!B18 -> 3 | D29: =Dotación!C18 -> 3 | E29: =Dotación!D18 -> 4 | F29: =Dotación!B19 -> 0 | G29: =Dotación!C19 -> 0 | H29: =Dotación!D19 -> 0 | I29: =Dotación!B20 -> 0 | J29: =Dotación!C20 -> 0 | K29: =Dotación!D20 -> 0 | L29: =Dotación!B21 -> 0 | M29: =Dotación!C21 -> 0 | N29: =Dotación!D21 -> 0 | O29: =Dotación!B22 -> 0 | P29: =Dotación!C22 -> 0 | Q29: =Dotación!D22 -> 0 | R29: =Dotación!B23 -> 0 | S29: =Dotación!C23 -> 0 | T29: =Dotación!D23 -> 0 | U29: =Dotación!B24 -> 0 | V29: =Dotación!C24 -> 0 | W29: =Dotación!D24 -> 0
A31: COCINEROS
X32: =SUM(C32:W32) -> 0
X33: =SUM(C33:W33) -> 0
X34: =SUM(C34:W34) -> 0
X35: =SUM(C35:W35) -> 0
X36: =SUM(C36:W36) -> 0
X37: =SUM(C37:W37) -> 0
A38: Asignados | C38: =COUNTA(C32:C37) -> 0 | D38: =COUNTA(D32:D37) -> 0 | E38: =COUNTA(E32:E37) -> 0 | F38: =COUNTA(F32:F37) -> 0 | G38: =COUNTA(G32:G37) -> 0 | H38: =COUNTA(H32:H37) -> 0 | I38: =COUNTA(I32:I37) -> 0 | J38: =COUNTA(J32:J37) -> 0 | ... W38: =COUNTA(W32:W37) -> 0 | X38: =SUM(X32:X37) -> 0
A39: Necesarios | C39: =Dotación!B28 -> 0 | D39: =Dotación!C28 -> 0 | E39: =Dotación!D28 -> 0 | F39: =Dotación!B29 -> 0 | G39: =Dotación!C29 -> 0 | H39: =Dotación!D29 -> 0 | I39: =Dotación!B30 -> 0 | J39: =Dotación!C30 -> 0 | K39: =Dotación!D30 -> 0 | L39: =Dotación!B31 -> 0 | M39: =Dotación!C31 -> 0 | N39: =Dotación!D31 -> 0 | O39: =Dotación!B32 -> 0 | P39: =Dotación!C32 -> 0 | Q39: =Dotación!D32 -> 0 | R39: =Dotación!B33 -> 0 | S39: =Dotación!C33 -> 0 | T39: =Dotación!D33 -> 0 | U39: =Dotación!B34 -> 0 | V39: =Dotación!C34 -> 0 | W39: =Dotación!D34 -> 0
A41: EXPO
X42: =SUM(C42:W42) -> 0
X43: =SUM(C43:W43) -> 0
X44: =SUM(C44:W44) -> 0
X45: =SUM(C45:W45) -> 0
A46: Asignados | C46: =COUNTA(C42:C45) -> 0 | D46: =COUNTA(D42:D45) -> 0 | E46: =COUNTA(E42:E45) -> 0 | F46: =COUNTA(F42:F45) -> 0 | G46: =COUNTA(G42:G45) -> 0 | H46: =COUNTA(H42:H45) -> 0 | I46: =COUNTA(I42:I45) -> 0 | J46: =COUNTA(J42:J45) -> 0 | ... W46: =COUNTA(W42:W45) -> 0 | X46: =SUM(X42:X45) -> 0
...

Sheet Dotación
A1: GPS GASTRONÓMICO
A2: Dotación de cocina — personal necesario por rol, día y turno
A3: Cargue, según la importancia de cada día y turno, cuántas personas necesita de cada rol (ej.: viernes y sábados, más dotación). Estos números alimentan el control del organigrama.
A6: BACHEROS / DISHWASHER
A7: DÍA | B7: T1 | C7: T2 | D7: T3 | E7: TOTAL DÍA
A8: Lunes | E8: =SUM(B8:D8) -> 0
A9: Martes | E9: =SUM(B9:D9) -> 0
A10: Miércoles | E10: =SUM(B10:D10) -> 0
A11: Jueves | E11: =SUM(B11:D11) -> 0
A12: Viernes | E12: =SUM(B12:D12) -> 0
A13: Sábado | E13: =SUM(B13:D13) -> 0
A14: Domingo | E14: =SUM(B14:D14) -> 0
A16: AYUDANTES
A17: DÍA | B17: T1 | C17: T2 | D17: T3 | E17: TOTAL DÍA
A18: Lunes | B18: 3 | C18: 3 | D18: 4 | E18: =SUM(B18:D18) -> 10
A19: Martes | E19: =SUM(B19:D19) -> 0
A20: Miércoles | E20: =SUM(B20:D20) -> 0
A21: Jueves | E21: =SUM(B21:D21) -> 0
A22: Viernes | E22: =SUM(B22:D22) -> 0
A23: Sábado | E23: =SUM(B23:D23) -> 0
A24: Domingo | E24: =SUM(B24:D24) -> 0
A26: COCINEROS
A27: DÍA | B27: T1 | C27: T2 | D27: T3 | E27: TOTAL DÍA
A28: Lunes | E28: =SUM(B28:D28) -> 0
A29: Martes | E29: =SUM(B29:D29) -> 0
A30: Miércoles | E30: =SUM(B30:D30) -> 0
A31: Jueves | E31: =SUM(B31:D31) -> 0
A32: Viernes | E32: =SUM(B32:D32) -> 0
A33: Sábado | E33: =SUM(B33:D33) -> 0
A34: Domingo | E34: =SUM(B34:D34) -> 0
A36: EXPO
A37: DÍA | B37: T1 | C37: T2 | D37: T3 | E37: TOTAL DÍA
A38: Lunes | E38: =SUM(B38:D38) -> 0
A39: Martes | E39: =SUM(B39:D39) -> 0
A40: Miércoles | E40: =SUM(B40:D40) -> 0
A41: Jueves | E41: =SUM(B41:D41) -> 0
A42: Viernes | E42: =SUM(B42:D42) -> 0
A43: Sábado | E43: =SUM(B43:D43) -> 0
A44: Domingo | E44: =SUM(B44:D44) -> 0

Sheet Producción
A1: GPS GASTRONÓMICO — Personal de Producción
A2: Días, roles, horarios y cantidad de empleados de producción (mise en place / preelaborados).
A4: DÍA | B4: ROL | C4: TAREA / ÁREA | D4: DESDE | E4: HASTA | F4: HORAS | G4: EMPLEADOS | H4: HORAS-HOMBRE | I4: NOMBRES / NOTAS
F5: =IF(AND(ISNUMBER(D5),ISNUMBER(E5)),IF(E5>D5,(E5-D5)*24,(E5+1-D5)*24),"") | H5: =IF(AND(ISNUMBER(F5),ISNUMBER(G5)),F5*G5,"")
F6: =IF(AND(ISNUMBER(D6),ISNUMBER(E6)),IF(E6>D6,(E6-D6)*24,(E6+1-D6)*24),"") | H6: =IF(AND(ISNUMBER(F6),ISNUMBER(G6)),F6*G6,"")
F7: =IF(AND(ISNUMBER(D7),ISNUMBER(E7)),IF(E7>D7,(E7-D7)*24,(E7+1-D7)*24),"") | H7: =IF(AND(ISNUMBER(F7),ISNUMBER(G7)),F7*G7,"")
F8: =IF(AND(ISNUMBER(D8),ISNUMBER(E8)),IF(E8>D8,(E8-D8)*24,(E8+1-D8)*24),"") | H8: =IF(AND(ISNUMBER(F8),ISNUMBER(G8)),F8*G8,"")
F9: =IF(AND(ISNUMBER(D9),ISNUMBER(E9)),IF(E9>D9,(E9-D9)*24,(E9+1-D9)*24),"") | H9: =IF(AND(ISNUMBER(F9),ISNUMBER(G9)),F9*G9,"")
F10: =IF(AND(ISNUMBER(D10),ISNUMBER(E10)),IF(E10>D10,(E10-D10)*24,(E10+1-D10)*24),"") | H10: =IF(AND(ISNUMBER(F10),ISNUMBER(G10)),F10*G10,"")
F11: =IF(AND(ISNUMBER(D11),ISNUMBER(E11)),IF(E11>D11,(E11-D11)*24,(E11+1-D11)*24),"") | H11: =IF(AND(ISNUMBER(F11),ISNUMBER(G11)),F11*G11,"")
F12: =IF(AND(ISNUMBER(D12),ISNUMBER(E12)),IF(E12>D12,(E12-D12)*24,(E12+1-D12)*24),"") | H12: =IF(AND(ISNUMBER(F12),ISNUMBER(G12)),F12*G12,"")
F13: =IF(AND(ISNUMBER(D13),ISNUMBER(E13)),IF(E13>D13,(E13-D13)*24,(E13+1-D13)*24),"") | H13: =IF(AND(ISNUMBER(F13),ISNUMBER(G13)),F13*G13,"")
F14: =IF(AND(ISNUMBER(D14),ISNUMBER(E14)),IF(E14>D14,(E14-D14)*24,(E14+1-D14)*24),"") | H14: =IF(AND(ISNUMBER(F14),ISNUMBER(G14)),F14*G14,"")
F15: =IF(AND(ISNUMBER(D15),ISNUMBER(E15)),IF(E15>D15,(E15-D15)*24,(E15+1-D15)*24),"") | H15: =IF(AND(ISNUMBER(F15),ISNUMBER(G15)),F15*G15,"")
F16: =IF(AND(ISNUMBER(D16),ISNUMBER(E16)),IF(E16>D16,(E16-D16)*24,(E16+1-D16)*24),"") | H16: =IF(AND(ISNUMBER(F16),ISNUMBER(G16)),F16*G16,"")
... F18: =IF(AND(ISNUMBER(D18),ISNUMBER(E18)),IF(E18>D18,(E18-D18)*24,(E18+1-D18)*24),"") | H18: =IF(AND(ISNUMBER(F18),ISNUMBER(G18)),F18*G18,"")
A19: TOTALES | G19: =SUM(G5:G18) -> 0 | H19: =SUM(H5:H18) -> 0

Sheet Instructivo
A1: CÓMO USAR EL ORGANIGRAMA DE COCINA
A3: 1. En "Organigrama Cocina", DEFINICIÓN DE TURNOS: ajuste nombre y horario de cada turno (T1, T2, T3).
A4: 2. En "Dotación": para cada rol (bacheros, ayudantes, cocineros, expo) cargue cuántas personas necesita por día y turno, según la importancia (viernes/sábados suelen requerir más).
A5: 3. En "Organigrama Cocina": dentro de cada rol, escriba los nombres de los empleados.
A6: 4. En cada cruce empleado / día / turno, escriba las HORAS que trabaja en ese turno.
A7: 5. TOTAL HORAS suma por empleado y por rol; abajo, el total de horas de cocina de la semana.
A8: 6. Asignados cuenta el personal de cada rol por turno y Necesarios lo compara con la Dotación: ROJO = falta, VERDE = cubierto.
A9: 7. En la hoja "Producción": cargue día, tarea/área, horario y cantidad de empleados; calcula horas y horas-hombre.
A10: 8. Imprima "Organigrama Cocina" y "Producción" (horizontal) para pegarlas en la cocina.
A11: Celdas crema = se completan a mano. Celdas grises = se calculan solas.
